<robot name="gz_example_robot">

  <!-- LINKS -->
  <link name="base_link">
    <visual>
      <geometry>
        <box size="0.24 0.16 0.12"/>
      </geometry>
      <origin rpy="0 0 0" xyz="0.08 0 0"/>
      <material name="white">
        <color rgba="1 1 1 1"/>
      </material>
    </visual>
  </link>

  <link name="left_wheel">
    <visual>
      <geometry>
        <cylinder length="0.04" radius="0.08" />/>
      </geometry>
      <origin rpy="0 0 0" xyz="0 0 0.02"/>
      <material name="blue">
        <color rgba="0.1 0.1 0.8 1"/>
      </material>
    </visual>
  </link>

  <link name="right_wheel">
    <visual>
      <geometry>
        <cylinder length="0.04" radius="0.08" />/>
      </geometry>
      <origin rpy="0 0 0" xyz="0 0 -0.02"/>
      <material name="blue">
        <color rgba="0.1 0.1 0.8 1"/>
      </material>
    </visual>
  </link>

  <link name="front_wheel">
    <visual>
      <geometry>
        <sphere radius="0.02" />/>
      </geometry>
      <origin rpy="0 0 0" xyz="0 0 0"/>
      <material name="blue">
        <color rgba="0.1 0.1 0.8 1"/>
      </material>
    </visual>
  </link>

  <link name="chassis_link">
  <!-- Convenient place to reference sensors to -->
  </link>    

  <!-- JOINTS -->  
    <joint name="left_wheel_joint" type="continuous">
    <parent link="base_link"/>
    <child link="left_wheel"/>
    <origin xyz="0 0.08 -0.02" rpy="-1.5708 0 0"/>
    <axis xyz="0 0 1"/>
  </joint>

  <joint name="right_wheel_joint" type="continuous">
    <parent link="base_link"/>
    <child link="right_wheel"/>
    <origin xyz="0 -0.08 -0.02" rpy="-1.5708 0 0"/>
    <axis xyz="0 0 1"/>
  </joint>

  <joint name="front_wheel_joint" type="fixed">
    <parent link="base_link"/>
    <child link="front_wheel"/>
    <origin xyz="0.18 0 -0.06" rpy="0 0 0"/>
  </joint>

  <joint name="chassis_joint" type="fixed">
    <parent link="base_link"/>
    <child link="chassis_link"/>
    <origin xyz="0.08 0 0.06" rpy="0 0 0"/>
  </joint>

</robot>